<?xml version="1.0" ?>
<sdf version="1.9">
  <model name="turtlebot3_waffle">
    <pose>0 0 0.01 0 0 0</pose>
    
    <!-- Base Link -->
    <link name="base_footprint"/>
    
    <link name="base_link">
      <pose>0 0 0.010 0 0 0</pose>
      <inertial>
        <mass>1.0</mass>
        <inertia>
          <ixx>0.001</ixx>
          <ixy>0.0</ixy>
          <ixz>0.0</ixz>
          <iyy>0.001</iyy>
          <iyz>0.0</iyz>
          <izz>0.001</izz>
        </inertia>
      </inertial>
      
      <collision name="base_collision">
        <geometry>
          <box>
            <size>0.140 0.140 0.143</size>
          </box>
        </geometry>
      </collision>
      
      <visual name="base_visual">
        <geometry>
          <box>
            <size>0.140 0.140 0.143</size>
          </box>
        </geometry>
        <material>
            <ambient>1 0 0 1</ambient>  <!-- Bright red -->
            <diffuse>1 0 0 1</diffuse>
            <specular>0.1 0.1 0.1 1</specular>
        </material>
      </visual>
    </link>
    
    <!-- Left Wheel -->
    <link name="wheel_left_link">
      <pose>0.0 0.08 -0.0285 -1.57 0 0</pose>
      <inertial>
        <mass>0.1</mass>
        <inertia>
          <ixx>0.001</ixx>
          <ixy>0.0</ixy>
          <ixz>0.0</ixz>
          <iyy>0.001</iyy>
          <iyz>0.0</iyz>
          <izz>0.001</izz>
        </inertia>
      </inertial>
      
      <collision name="wheel_left_collision">
        <geometry>
          <cylinder>
            <radius>0.033</radius>
            <length>0.018</length>
          </cylinder>
        </geometry>
        <surface>
          <friction>
            <ode>
              <mu>1.0</mu>
              <mu2>1.0</mu2>
              <slip1>0.0</slip1>
              <slip2>0.0</slip2>
            </ode>
          </friction>
        </surface>
      </collision>
      
      <visual name="wheel_left_visual">
        <geometry>
          <cylinder>
            <radius>0.033</radius>
            <length>0.018</length>
          </cylinder>
        </geometry>
        <material>
            <ambient>0 0 1 1</ambient>  <!-- Bright blue -->
            <diffuse>0 0 1 1</diffuse>
            <specular>0.1 0.1 0.1 1</specular>
        </material>
      </visual>
    </link>
    
    <!-- Right Wheel -->
    <link name="wheel_right_link">
      <pose>0.0 -0.08 -0.0285 -1.57 0 0</pose>
      <inertial>
        <mass>0.1</mass>
        <inertia>
          <ixx>0.001</ixx>
          <ixy>0.0</ixy>
          <ixz>0.0</ixz>
          <iyy>0.001</iyy>
          <iyz>0.0</iyz>
          <izz>0.001</izz>
        </inertia>
      </inertial>
      
      <collision name="wheel_right_collision">
        <geometry>
          <cylinder>
            <radius>0.033</radius>
            <length>0.018</length>
          </cylinder>
        </geometry>
        <surface>
          <friction>
            <ode>
              <mu>100.0</mu>
              <mu2>100.0</mu2>
              <slip1>0.0</slip1>
              <slip2>0.0</slip2>
            </ode>
          </friction>
        </surface>
      </collision>
      
      <visual name="wheel_right_visual">
        <geometry>
          <cylinder>
            <radius>0.033</radius>
            <length>0.018</length>
          </cylinder>
        </geometry>
        <material>
            <ambient>0 0 1 1</ambient>  <!-- Bright blue -->
            <diffuse>0 0 1 1</diffuse>
            <specular>0.1 0.1 0.1 1</specular>
        </material>
      </visual>
    </link>
    
    <!-- Caster Wheel -->
    <link name="caster_back_link">
        <pose>-0.081 0 -0.0285 0 0 0</pose>
      <inertial>
        <mass>0.01</mass>
        <inertia>
          <ixx>0.00001</ixx>
          <ixy>0.0</ixy>
          <ixz>0.0</ixz>
          <iyy>0.00001</iyy>
          <iyz>0.0</iyz>
          <izz>0.00001</izz>
        </inertia>
      </inertial>
      
      <collision name="caster_collision">
        <geometry>
          <sphere>
            <radius>0.005</radius>
          </sphere>
        </geometry>
        <surface>
          <friction>
            <ode>
              <mu>0.0</mu>
              <mu2>0.0</mu2>
              <slip1>1.0</slip1>
              <slip2>1.0</slip2>
            </ode>
          </friction>
        </surface>
      </collision>
    </link>
    
    <!-- LiDAR Link -->
    <link name="base_scan">
      <pose>-0.032 0 0.172 0 0 0</pose>
      <inertial>
        <mass>0.125</mass>
        <inertia>
          <ixx>0.001</ixx>
          <ixy>0.0</ixy>
          <ixz>0.0</ixz>
          <iyy>0.001</iyy>
          <iyz>0.0</iyz>
          <izz>0.001</izz>
        </inertia>
      </inertial>
      
      <collision name="lidar_collision">
        <geometry>
          <cylinder>
            <radius>0.0508</radius>
            <length>0.055</length>
          </cylinder>
        </geometry>
      </collision>
      
      <visual name="lidar_visual">
        <geometry>
          <cylinder>
            <radius>0.0508</radius>
            <length>0.055</length>
          </cylinder>
        </geometry>
        <material>
            <ambient>0 1 0 1</ambient>  <!-- Bright green -->
            <diffuse>0 1 0 1</diffuse>
            <specular>0.1 0.1 0.1 1</specular>
        </material>
      </visual>
      
      <!-- LiDAR Sensor with proper timestamp -->
      <sensor name="lidar" type="gpu_lidar">
        <topic>/scan</topic>
        <update_rate>10</update_rate>
        <gz_frame_id>base_scan</gz_frame_id>
        <always_on>true</always_on>
        <visualize>false</visualize>
        <lidar>
          <scan>
            <horizontal>
              <samples>360</samples>
              <resolution>1.0</resolution>
              <min_angle>0.0</min_angle>
              <max_angle>6.28</max_angle>
            </horizontal>
          </scan>
          <range>
            <min>0.12</min>
            <max>3.5</max>
            <resolution>0.015</resolution>
          </range>
          <noise>
            <type>gaussian</type>
            <mean>0.0</mean>
            <stddev>0.01</stddev>
          </noise>
        </lidar>
      </sensor>
    </link>
    
    <!-- Camera Link -->
    <link name="camera_rgb_frame">
      <pose>0.073 -0.011 0.084 0 0 0</pose>
      <inertial>
        <mass>0.035</mass>
        <inertia>
          <ixx>0.001</ixx>
          <ixy>0.0</ixy>
          <ixz>0.0</ixz>
          <iyy>0.001</iyy>
          <iyz>0.0</iyz>
          <izz>0.001</izz>
        </inertia>
      </inertial>
      
      <!-- Camera Sensor with proper timestamp -->
      <sensor name="camera" type="camera">
        <topic>/camera/image_raw</topic>
        <gz_frame_id>camera_rgb_frame</gz_frame_id>
        <camera>
          <horizontal_fov>1.085595</horizontal_fov>
          <image>
            <width>640</width>
            <height>480</height>
            <format>R8G8B8</format>
          </image>
          <clip>
            <near>0.05</near>
            <far>8.0</far>
          </clip>
          <noise>
            <type>gaussian</type>
            <mean>0.0</mean>
            <stddev>0.007</stddev>
          </noise>
        </camera>
        <always_on>true</always_on>
        <update_rate>30</update_rate>
        <visualize>false</visualize>
      </sensor>
    </link>
    
    <!-- Joints -->
    <joint name="base_joint" type="fixed">
      <parent>base_footprint</parent>
      <child>base_link</child>
    </joint>
    
    <joint name="wheel_left_joint" type="revolute">
      <parent>base_link</parent>
      <child>wheel_left_link</child>
      <axis>
        <xyz>0 0 1</xyz>
        <limit>
          <lower>-1.79769e+308</lower>
          <upper>1.79769e+308</upper>
        </limit>
      </axis>
    </joint>
    
    <joint name="wheel_right_joint" type="revolute">
      <parent>base_link</parent>
      <child>wheel_right_link</child>
      <axis>
        <xyz>0 0 1</xyz>
        <limit>
          <lower>-1.79769e+308</lower>
          <upper>1.79769e+308</upper>
        </limit>
      </axis>
    </joint>
    
    <joint name="caster_back_joint" type="ball">
      <parent>base_link</parent>
      <child>caster_back_link</child>
    </joint>
    
    <joint name="lidar_joint" type="fixed">
      <parent>base_link</parent>
      <child>base_scan</child>
    </joint>
    
    <joint name="camera_joint" type="fixed">
      <parent>base_link</parent>
      <child>camera_rgb_frame</child>
    </joint>
    
    <!-- Diff Drive Plugin -->
    <plugin filename="gz-sim-diff-drive-system" name="gz::sim::systems::DiffDrive">
      <left_joint>wheel_left_joint</left_joint>
      <right_joint>wheel_right_joint</right_joint>
      <wheel_separation>0.160</wheel_separation>
      <wheel_radius>0.033</wheel_radius>
      <odom_publish_frequency>50</odom_publish_frequency>
      <topic>/cmd_vel</topic>
      <odom_topic>/odom</odom_topic>
      <frame_id>odom</frame_id>
      <child_frame_id>base_footprint</child_frame_id>
    </plugin>
    
    <!-- Joint State Publisher -->
    <plugin filename="gz-sim-joint-state-publisher-system" name="gz::sim::systems::JointStatePublisher">
      <topic>/joint_states</topic>
    </plugin>
    
    <!-- Pose Publisher -->
    <plugin filename="gz-sim-pose-publisher-system" name="gz::sim::systems::PosePublisher">
      <publish_link_pose>true</publish_link_pose>
      <publish_sensor_pose>true</publish_sensor_pose>
      <publish_collision_pose>false</publish_collision_pose>
      <publish_visual_pose>false</publish_visual_pose>
      <publish_nested_model_pose>true</publish_nested_model_pose>
      <update_frequency>50</update_frequency>
    </plugin>
    
  </model>
</sdf>